<?xml version="1.0" encoding="UTF-8"?>
<!-- Generated by org.testng.reporters.JUnitXMLReporter -->
<testsuite ignored="0" hostname="DESKTOP-V6E6QIF" failures="4" tests="18" name="firefoxTest" time="109.098" errors="0" timestamp="2025-05-17T20:20:00 EDT">
  <testcase classname="testCases.TC006_AddAffiliate" name="login" time="2.771">
    <skipped/>
  </testcase> <!-- login -->
  <testcase classname="testCases.TC006_AddAffiliate" name="login" time="0.084">
    <skipped/>
  </testcase> <!-- login -->
  <testcase classname="testCases.TC006_AddAffiliate" name="login" time="0.076">
    <failure type="java.lang.AssertionError" message="Test failed due to unexpected exception.">
      <![CDATA[java.lang.AssertionError: Test failed due to unexpected exception.
at testCases.TC006_AddAffiliate.login(TC006_AddAffiliate.java:65)
at java.base/java.util.ArrayList.forEach(ArrayList.java:1596)
at java.base/java.util.concurrent.FutureTask.run(FutureTask.java:317)
at java.base/java.util.concurrent.ThreadPoolExecutor.runWorker(ThreadPoolExecutor.java:1144)
at java.base/java.util.concurrent.ThreadPoolExecutor$Worker.run(ThreadPoolExecutor.java:642)
at java.base/java.lang.Thread.run(Thread.java:1583)
... Removed 16 stack frames]]>
    </failure>
  </testcase> <!-- login -->
  <testcase classname="testCases.TC01_LaunchApplication" name="testLaunchApplication" time="0.038"/>
  <testcase classname="testCases.TC03_AddToCart" name="testAddToCart" time="1.435">
    <skipped/>
  </testcase> <!-- testAddToCart -->
  <testcase classname="testCases.TC03_AddToCart" name="testAddToCart" time="1.112">
    <skipped/>
  </testcase> <!-- testAddToCart -->
  <testcase classname="testCases.TC03_AddToCart" name="testAddToCart" time="0.079">
    <failure type="java.lang.AssertionError" message="Test failed due to unexpected error.">
      <![CDATA[java.lang.AssertionError: Test failed due to unexpected error.
at testCases.TC03_AddToCart.testAddToCart(TC03_AddToCart.java:53)
at java.base/java.util.ArrayList.forEach(ArrayList.java:1596)
at java.base/java.util.concurrent.FutureTask.run(FutureTask.java:317)
at java.base/java.util.concurrent.ThreadPoolExecutor.runWorker(ThreadPoolExecutor.java:1144)
at java.base/java.util.concurrent.ThreadPoolExecutor$Worker.run(ThreadPoolExecutor.java:642)
at java.base/java.lang.Thread.run(Thread.java:1583)
... Removed 16 stack frames]]>
    </failure>
  </testcase> <!-- testAddToCart -->
  <testcase classname="testCases.TC_04_CompletePurchase" name="checkOut" time="1.186">
    <skipped/>
  </testcase> <!-- checkOut -->
  <testcase classname="testCases.TC_04_CompletePurchase" name="checkOut" time="0.767">
    <skipped/>
  </testcase> <!-- checkOut -->
  <testcase classname="testCases.TC_04_CompletePurchase" name="checkOut" time="0.346">
    <failure type="java.lang.AssertionError" message="Test failed due to unexpected error.">
      <![CDATA[java.lang.AssertionError: Test failed due to unexpected error.
at testCases.TC_04_CompletePurchase.checkOut(TC_04_CompletePurchase.java:78)
at java.base/java.util.ArrayList.forEach(ArrayList.java:1596)
at java.base/java.util.concurrent.FutureTask.run(FutureTask.java:317)
at java.base/java.util.concurrent.ThreadPoolExecutor.runWorker(ThreadPoolExecutor.java:1144)
at java.base/java.util.concurrent.ThreadPoolExecutor$Worker.run(ThreadPoolExecutor.java:642)
at java.base/java.lang.Thread.run(Thread.java:1583)
... Removed 16 stack frames]]>
    </failure>
  </testcase> <!-- checkOut -->
  <testcase classname="testCases.TC02_Login" name="testLogin" time="2.429"/>
  <testcase classname="testCases.TC02_Login" name="testLogin" time="2.184"/>
  <testcase classname="testCases.TC02_Login" name="testLogin" time="2.124"/>
  <testcase classname="testCases.TC02_Login" name="testLogin" time="2.15"/>
  <testcase classname="testCases.TC02_Login" name="testLogin" time="1.781"/>
  <testcase classname="testCases.TC05__AddToWishList" name="addToWishList" time="0.891">
    <skipped/>
  </testcase> <!-- addToWishList -->
  <testcase classname="testCases.TC05__AddToWishList" name="addToWishList" time="0.734">
    <skipped/>
  </testcase> <!-- addToWishList -->
  <testcase classname="testCases.TC05__AddToWishList" name="addToWishList" time="0.319">
    <failure type="java.lang.AssertionError" message="Test failed due to unexpected exception.">
      <![CDATA[java.lang.AssertionError: Test failed due to unexpected exception.
at testCases.TC05__AddToWishList.addToWishList(TC05__AddToWishList.java:65)
at java.base/java.util.ArrayList.forEach(ArrayList.java:1596)
at java.base/java.util.concurrent.FutureTask.run(FutureTask.java:317)
at java.base/java.util.concurrent.ThreadPoolExecutor.runWorker(ThreadPoolExecutor.java:1144)
at java.base/java.util.concurrent.ThreadPoolExecutor$Worker.run(ThreadPoolExecutor.java:642)
at java.base/java.lang.Thread.run(Thread.java:1583)
... Removed 16 stack frames]]>
    </failure>
  </testcase> <!-- addToWishList -->
</testsuite> <!-- firefoxTest -->
